<?xml version="1.0"?>
<robot name="tennis_bot" xmlns:xacro="http://ros.org/wiki/xacro">

  <!-- Define robot constants -->
  <xacro:property name="base_width" value="0.31"/>
  <xacro:property name="base_length" value="0.42"/>
  <xacro:property name="base_height" value="0.16"/>

  <xacro:property name="wheel_radius" value="0.10"/>
  <xacro:property name="wheel_width" value="0.04"/>
  <xacro:property name="wheel_ygap" value="0.025"/>
  <xacro:property name="wheel_zoff" value="0.05"/>
  <xacro:property name="wheel_xoff" value="0.12"/>
  
  <xacro:property name="arm_width" value="0.20"/>
  <xacro:property name="arm_length" value="0.20"/>
  <xacro:property name="arm_height" value="0.02"/>
  <xacro:property name="arm_ygap" value="-0.01"/>
  <xacro:property name="arm_zoff" value="0.02"/>
  <xacro:property name="arm_xoff" value="-0.21"/>

  <!-- Define intertial property macros  -->
  <xacro:macro name="box_inertia" params="m w h d">
    <inertial>
      <origin xyz="0 0 0" rpy="${pi/2} 0 ${pi/2}"/>
      <mass value="${m}"/>
      <inertia ixx="${(m/12) * (h*h + d*d)}" ixy="0.0" ixz="0.0" iyy="${(m/12) * (w*w + d*d)}" iyz="0.0" izz="${(m/12) * (w*w + h*h)}"/>
    </inertial>
  </xacro:macro>

  <xacro:macro name="cylinder_inertia" params="m r h">
    <inertial>
      <origin xyz="0 0 0" rpy="${pi/2} 0 0" />
      <mass value="${m}"/>
      <inertia ixx="${(m/12) * (3*r*r + h*h)}" ixy = "0" ixz = "0" iyy="${(m/12) * (3*r*r + h*h)}" iyz = "0" izz="${(m/2) * (r*r)}"/>
    </inertial>
  </xacro:macro>

  <xacro:macro name="sphere_inertia" params="m r">
    <inertial>
      <mass value="${m}"/>
      <inertia ixx="${(2/5) * m * (r*r)}" ixy="0.0" ixz="0.0" iyy="${(2/5) * m * (r*r)}" iyz="0.0" izz="${(2/5) * m * (r*r)}"/>
    </inertial>
  </xacro:macro>

  <!-- Robot Base -->
  <link name="base_link">
    <visual>
      <geometry>
        <box size="${base_length} ${base_width} ${base_height}"/>
      </geometry>
      <material name="White">
        <color rgba="0.9 0.9 0.9 1"/>
      </material>
    </visual>
    
    <collision>
      <geometry>
        <box size="${base_length} ${base_width} ${base_height}"/>
      </geometry>
    </collision>

    <xacro:box_inertia m="15" w="${base_width}" d="${base_length}" h="${base_height}"/>
  </link>

  <link name="base_top_link">
    <visual>
      <geometry>
        <box size="0.38 0.27 0.02"/>
      </geometry>
      <material name="White">
        <color rgba="0.9 0.9 0.9 1"/>
      </material>
    </visual>

    <collision>
      <geometry>
        <box size="0.38 0.27 0.02"/>
      </geometry>
    </collision>
  </link>

  <joint name="base_top_joint" type="fixed">
    <parent link="base_link"/>
    <child link="base_top_link"/>
    <origin xyz="0.0 0.0 0.08" rpy="0 0 0"/>
  </joint>

  <!-- Robot Footprint -->
  <link name="base_footprint"/>

  <joint name="base_joint" type="fixed">
    <parent link="base_link"/>
    <child link="base_footprint"/>
    <origin xyz="0.0 0.0 ${-(wheel_radius+wheel_zoff)}" rpy="0 0 0"/>
  </joint>
  	
  <!-- Wheels -->
  <xacro:macro name="wheel" params="prefix x_reflect y_reflect">
    <link name="${prefix}_link">
      <visual>
        <origin xyz="0 0 0" rpy="${pi/2} 0 0"/>
        <geometry>
            <cylinder radius="${wheel_radius}" length="${wheel_width}"/>
        </geometry>
        <material name="White">
          <color rgba="0.9 0.9 0.9 1"/>
        </material>
      </visual>

      <collision>
        <origin xyz="0 0 0" rpy="${pi/2} 0 0"/>
        <geometry>
          <cylinder radius="${wheel_radius}" length="${wheel_width}"/>
        </geometry>
      </collision>

      <xacro:cylinder_inertia m="0.5" r="${wheel_radius}" h="${wheel_width}"/>

    </link>

    <joint name="${prefix}_joint" type="continuous">
      <parent link="base_link"/>
      <child link="${prefix}_link"/>
      <origin xyz="${x_reflect*wheel_xoff} ${y_reflect*(base_width/2+wheel_ygap)} ${-wheel_zoff}" rpy="0 0 0"/>
      <axis xyz="0 1 0"/>
    </joint>
  </xacro:macro>

  <xacro:wheel prefix="drivewhl_b_l" x_reflect="-1" y_reflect="1" />
  <xacro:wheel prefix="drivewhl_b_r" x_reflect="-1" y_reflect="-1" />
  <xacro:wheel prefix="drivewhl_f_l" x_reflect="1" y_reflect="1" />
  <xacro:wheel prefix="drivewhl_f_r" x_reflect="1" y_reflect="-1" />
  
  <!--Robot arms -->
  <xacro:macro name="arm" params="prefix x_reflect y_reflect orientation">
    <link name="${prefix}_link">
      <visual>
        <origin xyz="0.10 0 0" rpy="${pi/2} 0 0"/>
        <geometry>
          <box size="${arm_length} ${arm_width} ${arm_height}"/>
        </geometry>
        <material name="White">
          <color rgba="0.9 0.9 0.9 1"/>
        </material>
      </visual>
      
      <collision>
        <origin xyz="0 0 0" rpy="${pi/2} 0 0"/>
        <geometry>
            <box size="${arm_length} ${arm_width} ${arm_height}"/>
        </geometry>
      </collision>
      
      <xacro:box_inertia m="2" w="${arm_width}" d="${arm_length}" h="${arm_height}"/>
    </link>
    
    <joint name="${prefix}_joint" type="continuous">
      <parent link="base_link"/>
      <child link="${prefix}_link"/>
      <origin xyz="${x_reflect*arm_xoff} ${y_reflect*(base_width/2+arm_ygap)} ${-arm_zoff}" rpy="0 0 ${orientation}"/>
      <axis xyz="0 0 1"/>
    </joint>
  </xacro:macro>
  
  <xacro:arm prefix="arm_l" x_reflect="-1" y_reflect="1" orientation="1"/>
  <xacro:arm prefix="arm_r" x_reflect="-1" y_reflect="-1" orientation="-1"/>
  
  <xacro:macro name="cylinders" params ="prefix radius length parent y_orientation z_orientation x_pos y_pos z_pos">
    <link name="${prefix}_link">
      <visual>
        <geometry>
          <cylinder radius="${radius}" length="${length}"/>
        </geometry>
        <material name="White">
          <color rgba="0.9 0.9 0.9 1"/>
        </material>
      </visual>
      
      <collision>
        <geometry>
          <cylinder radius="${radius}" length="${length}"/>
        </geometry>
      </collision>
    </link>
  
    <joint name="${prefix}_joint" type="fixed">
      <parent link="${parent}_link"/>
      <child link="${prefix}_link"/>
      <origin xyz="${x_pos} ${y_pos} ${z_pos}" rpy="0 ${y_orientation} ${z_orientation}"/>
    </joint>  
  </xacro:macro>

  <xacro:cylinders prefix="cylinder_1" radius="0.01" length="0.2" parent="arm_l" y_orientation="0" z_orientation="0" x_pos="0.2" y_pos="0" z_pos="0"/>
  <xacro:cylinders prefix="cylinder_2" radius="0.01" length="0.2" parent="arm_r" y_orientation="0" z_orientation="0" x_pos="0.2" y_pos="0" z_pos="0"/>
  <xacro:cylinders prefix="cylinder_base_l" radius="0.02" length="0.38" parent="base" y_orientation="${pi/2}" z_orientation="0" x_pos="0" y_pos="0.135" z_pos="0.07"/>
  <xacro:cylinders prefix="cylinder_base_r" radius="0.02" length="0.38" parent="base" y_orientation="${pi/2}" z_orientation="0" x_pos="0" y_pos="-0.135" z_pos="0.07"/>
  <xacro:cylinders prefix="cylinder_base_f" radius="0.02" length="0.27" parent="base" y_orientation="${pi/2}" z_orientation="${pi/2}" x_pos="0.19" y_pos="0" z_pos="0.07"/>
  <xacro:cylinders prefix="cylinder_base_b" radius="0.02" length="0.27" parent="base" y_orientation="${pi/2}" z_orientation="${pi/2}" x_pos="-0.19" y_pos="0" z_pos="0.07"/>

</robot>
